streamlit.errors.StreamlitSecretNotFoundError: No secrets found. Valid paths for a secrets.toml file or secret directories are: /home/runner/.streamlit/secrets.toml, /home/runner/workspace/.streamlit/secrets.toml

Traceback:
File "/home/runner/workspace/.pythonlibs/lib/python3.11/site-packages/streamlit/runtime/scriptrunner/exec_code.py", line 121, in exec_func_with_error_handling
    result = func()
             ^^^^^^
File "/home/runner/workspace/.pythonlibs/lib/python3.11/site-packages/streamlit/runtime/scriptrunner/script_runner.py", line 639, in code_to_exec
    _mpa_v1(self._main_script_path)
File "/home/runner/workspace/.pythonlibs/lib/python3.11/site-packages/streamlit/runtime/scriptrunner/script_runner.py", line 159, in _mpa_v1
    page.run()
File "/home/runner/workspace/.pythonlibs/lib/python3.11/site-packages/streamlit/navigation/page.py", line 297, in run
    exec(code, module.__dict__)
File "/home/runner/workspace/pages/01_Upload_Data.py", line 100, in <module>
    current_count = get_dataset_count(st.session_state.user_id)
                    ^^^^^^^^^^^^^^^^^^^^^^^^^^^^^^^^^^^^^^^^^^^
File "/home/runner/workspace/utils/access_control.py", line 166, in get_dataset_count
    return execute_with_retry(_count_datasets_operation)
           ^^^^^^^^^^^^^^^^^^^^^^^^^^^^^^^^^^^^^^^^^^^^^
File "/home/runner/workspace/utils/database.py", line 136, in execute_with_retry
    return operation()
           ^^^^^^^^^^^
File "/home/runner/workspace/utils/access_control.py", line 161, in _count_datasets_operation
    with sa.create_engine(st.secrets["postgresql"]).connect() as conn:
                          ~~~~~~~~~~^^^^^^^^^^^^^^
File "/home/runner/workspace/.pythonlibs/lib/python3.11/site-packages/streamlit/runtime/secrets.py", line 470, in __getitem__
    value = self._parse()[key]
            ^^^^^^^^^^^^^
File "/home/runner/workspace/.pythonlibs/lib/python3.11/site-packages/streamlit/runtime/secrets.py", line 372, in _parse
    raise StreamlitSecretNotFoundError(error_msg)